Workbook
Name EV_make_and_model: EV_DB[Make & Model]
Name ICE_make_and_model: ICE_DB[Make + Model]
Name Unique_chargers: Charger_DB[Charger type]

Sheet TCO Dashboard
B2: Cells Highlighted in Green are INPUT Cells
B5: 1. Enter Duty Dycle Requirements | E5: 2. Review EV Recommendations | J5: 3. Review ICE vehicles
B6: Duty cycle | E6: Make & Model | F6: Type | G6: Price | H6: Battery Size | J6: Make & Model | K6: price | L6: Payload (lbs) | M6: Fuel type
B7: Required daily distance (km) | C7: 200 | E7: {=IFERROR(INDEX(_xlfn._xlws.FILTER(EV_DB[Make & Model], (EV_DB[Category]=C9) * (EV_DB[Range (km)]>=C7) * (EV_DB[Max Payload, lbs.]>=C8) * (EV_DB[Refrigerated Unit]=C10) * ((EV_DB[Range (km)]<>"") * (EV_DB[Max Payload, lbs.]<>"")), "No EV Matches Your Duty Cycle"), _xlfn.SEQUENCE(10,1)), "")} -> Ram Electric 1500 Large Battery | F7: {=IFERROR(INDEX(_xlfn._xlws.FILTER(EV_DB[Type/Use Case], (EV_DB[Category]=C9) * (EV_DB[Range (km)]>=C7) * (EV_DB[Max Payload, lbs.]>=C8) * (EV_DB[Refrigerated Unit]=C10) * ((EV_DB[Range (km)]<>"") * (EV_DB[Max Payload, lbs.]<>"")), "No EV Matches Your Duty Cycle"), _xlfn.SEQUENCE(10,1)), "")} -> Pick-up truck | G7: {=IFERROR(INDEX(_xlfn._xlws.FILTER(EV_DB[Cost, $MSRP CAD], (EV_DB[Category]=C9) * (EV_DB[Range (km)]>=C7) * (EV_DB[Max Payload, lbs.]>=C8) * (EV_DB[Refrigerated Unit]=C10) * ((EV_DB[Range (km)]<>"") * (EV_DB[Max Payload, lbs.]<>"")), "No EV Matches Your Duty Cycle"), _xlfn.SEQUENCE(10,1)), "")} -> 81085 | H7: {=IFERROR(INDEX(_xlfn._xlws.FILTER(EV_DB[Battery Size, kWh], (EV_DB[Category]=C9) * (EV_DB[Range (km)]>=C7) * (EV_DB[Max Payload, lbs.]>=C8) * (EV_DB[Refrigerated Unit]=C10) * ((EV_DB[Range (km)]<>"") * (EV_DB[Max Payload, lbs.]<>"")), "No EV Matches Your Duty Cycle"), _xlfn.SEQUENCE(10,1)), "")} -> 229kwh | J7: {=IFERROR(INDEX(_xlfn._xlws.FILTER(ICE_DB[Make + Model], (ICE_DB[Category]=C9) * (ICE_DB[Payload (lbs)]>=C8) * (ICE_DB[Payload (lbs)]<>""), "No ICE vehicle in our database matches Your Duty Cycle"), _xlfn.SEQUENCE(10,1)), "")} -> Ford Transit | K7: {=IFERROR(INDEX(_xlfn._xlws.FILTER(ICE_DB[Purchase price ($ CAD)], (ICE_DB[Category]=C9) * (ICE_DB[Payload (lbs)]>=C8) * (ICE_DB[Payload (lbs)]<>""), "No ICE vehicle in our database matches Your Duty Cycle"), _xlfn.SEQUENCE(10,1)), "")} -> 68580 | L7: {=IFERROR(INDEX(_xlfn._xlws.FILTER(ICE_DB[Payload (lbs)], (ICE_DB[Category]=C9) * (ICE_DB[Payload (lbs)]>=C8) * (ICE_DB[Payload (lbs)]<>""), "No ICE vehicle in our database matches Your Duty Cycle"), _xlfn.SEQUENCE(10,1)), "")} -> 3148 | M7: {=IFERROR(INDEX(_xlfn._xlws.FILTER(ICE_DB[Fuel type], (ICE_DB[Category]=C9) * (ICE_DB[Payload (lbs)]>=C8) * (ICE_DB[Payload (lbs)]<>""), "No ICE vehicle in our database matches Your Duty Cycle"), _xlfn.SEQUENCE(10,1)), "")} -> Diesel
B8: Maximum payload (lbs) | C8: 500 | E8: GMC GMC Sierra EV Denali Edition 1 | F8: Pick-up truck | G8: 92290 | H8: 205kwh | J8: Ford Transit High Roof Refrigerated | K8: 71000 | L8: 4000 | M8: Gasoline
B9: Category | C9: Light Duty | E9: Chevrolet Silverado EV 3WT Max Range | F9: Pick-up truck | G9: 85833 | H9: 205kwh | J9: Mercedes Sprinter Cargo Van Low Roof | K9: 59980 | L9: 3780 | M9: Gasoline
B10: Refrigeration required? | C10: No | E10: Chevrolet Silverado EV LT E4WD | F10: Pick-up truck | G10: 95833 | H10: 170kwh | J10: Mercedes Sprinter Cargo Van High Roof | K10: 67400 | L10: 4210 | M10: Diesel
E11: Ford F 150 Lightning | F11: Pick-up truck | G11: 62890 | H11: 98 kWh | J11: Ford F-150 | K11: 54000 | L11: 3325 | M11: Gasoline
E12: Ford F 150 Lightning Flash and Lariat | F12: Pick-up truck | G12: 79090 | H12: 131 kWh | J12: Chevy Silverado 1500 WT | K12: 61000 | L12: 2270 | M12: Gasoline
E13: Mercedes-Benz eSprinter (2500) | F13: Delivery van | G13: 99500 | H13: 113 kWh | J13: Chevrolet Express 2500 Cargo Van | K13: 56033 | L13: 3496 | M13: Gasoline
E14: RAM ProMaster Van | F14: Cargo van | G14: 119000 | H14: 110kWh | J14: Ram ProMaster Van | K14: 80000 | L14: 4820 | M14: Gasoline
E15: Rivian R1T Dual | F15: Pick-up truck | G15: 77900 | H15: 135 kWh | J15: Isuzu NPR | K15: 60000 | L15: 8800 | M15: Gasoline
E16: Ford E-Transit | F16: Cargo, delivery, work van | G16: 68705 | H16: 68 kWh | J16: Ford Escape | K16: 36954 | L16: 1013 | M16: Gasoline
B18: 4. Select vehicles & charger to perform TCO with | E18: 5. Operational inputs | G18: Default values | I18: 6. Financing inputs | L18: Default values
B19: Select EV: | C19: Chevrolet Silverado EV LT E4WD | E19: Province | F19: ON | I19: ICE vehicle down payment as % of MSRP | K19: 0.05 | L19: 0.05
B20: Select charger: | C20: L2 7.2kW | E20: Annual vehicle KM's travelled | F20: 30000 | G20: 30000 | I20: ICE vehicle loan interest rate (APR) | K20: 0.07 | L20: 0.07
B21: Select ICE vehicle: | C21: Ford F-150 | E21: How many EV vehicles can share one charger? | F21: 1 | G21: 2 | I21: ICE vehicle loan term (years) | K21: 7 | L21: 7
I22: EV down payment as % of MSRP | K22: 0.05 | L22: 0.05
I23: EV loan interest rate | K23: 0.07 | L23: 0.07
I24: EV loan term (years) | K24: 7 | L24: 7
B26: 7. Optional manual overrides
C27: ICE | D27: Override | E27: EV | F27: Override
B28: Annual Maintenance costs | C28: 0 | D28: FALSE | E28: 0 | F28: FALSE
B29: Vehicle purchase price | C29: 0 | D29: FALSE | E29: 0 | F29: FALSE | H29: Add: | J29: Notes for shares charging hub
B30: Fuel/ energy costs ($/L , $/kWh) | C30: 0 | D30: FALSE | E30: 0 | F30: FALSE | H30: km's travelled | J30: % of charging that will be done by charging hub | K30: reduce energy cost and infrastructure by %
B31: Charger infrastructure cost | C31: 0 | D31: FALSE | E31: 0 | F31: FALSE | H31: $kWh | J31: Reduced charger to truck ratios. A lower number of chargers per unit of kWh. A benefit of economies of scale
B32: Additional Vehicle Rebate | C32: 0 | D32: FALSE | E32: 0 | F32: FALSE | H32: CFR price ranges | J32: Leasing scenario needs to be built
B33: Additional Charging Infrastructure Rebate | C33: 0 | D33: FALSE | E33: 0 | F33: FALSE | J33: Also need to acknowledge that depot infrastructure will
B36: Scenario 1: Purchase Upfront
P38: Average Cost per KM - ICE
P39: ='Cost analysis - purchase'!P12/('TCO Dashboard'!F20*10) -> 0.56165841
P40: Average Cost per KM - EV
P41: ='Cost analysis - purchase'!AC12/('TCO Dashboard'!F20*10) -> 0.48312364
P42: Total Savings- 7 years
P43: ='Cost analysis - purchase'!P12-'Cost analysis - purchase'!AC12 -> 23560.431
Q48: ICE | R48: EV
P49: Average daily km | Q49: =C7 -> 200 | R49: =C7 -> 200
P50: Average Annual km | Q50: =F20 -> 30000 | R50: =F20 -> 30000
P52: Vehicle cost (MSRP) | Q52: ='Cost analysis - purchase'!B6 -> 54000 | R52: ='Cost analysis - purchase'!B7 -> 95833
P53: Available funding for vehicle | Q53: ='Cost analysis - purchase'!B51 -> 0 | R53: ='Cost analysis - purchase'!B50 -> 10000
...

Sheet Cost analysis - purchase
A1: Present value | B1: Value | C1: Unit | D1: Source | E1: Notes | F1: From input tab | H1: Scenario 1: Purchase Upfront
A2: Discount rate | B2: =0.04 -> 0.04 | C2: % | D2: Input | E2: - | F2: calculated data | H2: Year | I2: ICE - Purchase cost | J2: ICE - Fuel cost | K2: ICE - Carbon tax | L2: ICE - Tires & Maintenance cost | M2: ICE - salvage value | O2: ICE - vehicle insurance | P2: ICE - Total cost | Q2: ICE - Cumulative Total Cost | R2: ICE- depreciation | S2: EV - Purchase cost | T2: EV - Vehicle + chargers Total rebate | U2: EV - CFR/LCFS | V2: EV - Charging cost | W2: EV - Tires & Maintenance Cost | X2: EV - Charging infrastructure cost | Y2: EV - Charger infrastructure maintenance | Z2: EV - Salvage value | AA2: EV - Charger Salvage value | AB2: EV- vehicle insurance | AC2: EV -Total cost | AD2: EV - Cumulative Total Cost | AE2: EV - depreciation | AF2: Chargers - depreciation | AG2: Discount Factor | AH2: Cumulative Savings | AI2: ICE -Total discounted cost | AJ2: EV - Total discounted cost
H3: 0 | J3: 0 | L3: 0 | P3: =SUM(I3:O3) -> 0 | Q3: =P3 -> 0 | R3: 0 | V3: 0 | W3: 0 | AC3: =SUM(S3:AB3) -> 0 | AD3: =AC3 -> 0 | AE3: 0 | AF3: 0 | AH3: =MAX(Q3-AD3,0) -> 0 | AI3: =AG3*P3 -> 0 | AJ3: =AG3*AC3 -> 0
H4: 1 | I4: =B6 -> 54000 | J4: =(B$20*B$21)*B$9 -> 5208.63 | K4: =B20*B21*B40 -> 0 | L4: =B14*B21 -> 10500 | O4: =B55*B6 -> 1620 | P4: =SUM(I4:O4) -> 71328.63 | Q4: =Q3+P4 -> 71328.63 | R4: =($I$4-SUM($R$3:R3))*B$25 -> 8100 | S4: =B7 -> 95833 | T4: =-(B50+B52) -> -10000 | U4: =-B41-B43 -> -1820.3388 | V4: =(B$19*B$10)*B$21 -> 1648.416 | W4: =B$15*B$21 -> 5400 | X4: =B37*B38 -> 15214.072 | Y4: =X4*B17 -> 608.56286 | AB4: =B7*B54 -> 3833.32 | AC4: =SUM(S4:AB4) -> 110717.03 | AD4: =AC4 -> 110717.03 | AE4: =($S$4)*B$26 -> 14374.95 | AF4: =0.5*($B$37)*IF('TCO Dashboard'!C20 = 'Charger database'!A6,B$28,B$27) -> 2282.1107 | AG4: =1/(1+$B$2)^H4 -> 0.96153846 | AH4: =MAX(Q4-AD4,0) -> 0 | AI4: =AG4*P4 -> 68585.221 | AJ4: =AG4*AC4 -> 106458.68
A5: Purchase prices | B5: Value | C5: Unit | D5: Source | E5: Notes | H5: 2 | I5: 0 | J5: =J4*(1+B$11) -> 5469.0615 | K5: =B20*B21*B40 -> 0 | L5: =L4*(1+B$16) -> 10710 | O5: =B55*B6 -> 1620 | P5: =SUM(I5:O5) -> 17799.061 | Q5: =Q4+P5 -> 89127.692 | R5: =($I$4-SUM($R$3:R4))*B$25 -> 6885 | S5: 0 | T5: 0 | U5: =U4-(U4*B$48) -> -1674.7117 | V5: =V4*(1+B$12) -> 1697.8685 | W5: =W4*(1+B$16) -> 5508 | X5: 0 | Y5: =Y4+(1.02) -> 609.58286 | AB5: =B7*B54 -> 3833.32 | AC5: =SUM(S5:AB5) -> 9974.0596 | AD5: =AD4+AC5 -> 120691.09 | AE5: =($S$4-SUM($AE$4:AE4))*B$26 -> 12218.708 | AF5: =($B$37-SUM($AF4:AF$4))*IF('TCO Dashboard'!C$20 = 'Charger database'!A$6,B$28,B$27) -> 3879.5883 | AG5: =1/(1+$B$2)^H5 -> 0.92455621 | AH5: =MAX(Q5-AD5,0) -> 0 | AI5: =AG5*P5 -> 16456.233 | AJ5: =AG5*AC5 -> 9221.5788
A6: Chosen ICE vehicle MSRP | B6: =IF('TCO Dashboard'!D29 = TRUE, 'TCO Dashboard'!C29,_xlfn.XLOOKUP('TCO Dashboard'!C21,ICE_DB[Make + Model],ICE_DB[Purchase price ($ CAD)])) -> 54000 | C6: $ (CAD) | D6: ICE database | E6: - | H6: 3 | I6: 0 | J6: =J5*(1+B$11) -> 5742.5146 | K6: =B20*B21*B40 -> 0 | L6: =L5*(1+B$16) -> 10924.2 | O6: =B55*B6 -> 1620 | P6: =SUM(I6:O6) -> 18286.715 | Q6: =Q5+P6 -> 107414.41 | R6: =($I$4-SUM($R$3:R5))*B$25 -> 5852.25 | S6: 0 | T6: 0 | U6: =U5-(U5*B$48) -> -1540.7348 | V6: =V5*(1+B$12) -> 1748.8045 | W6: =W5*(1+B$16) -> 5618.16 | X6: 0 | Y6: =Y5+(1.02) -> 610.60286 | AB6: =B7*B54 -> 3833.32 | AC6: =SUM(S6:AB6) -> 10270.153 | AD6: =AD5+AC6 -> 130961.24 | AE6: =($S$4-SUM($AE$4:AE5))*B$26 -> 10385.901 | AF6: =($B$37-SUM($AF$4:AF5))*IF('TCO Dashboard'!C$20 = 'Charger database'!A$6,B$28,B$27) -> 2715.7118 | AG6: =1/(1+$B$2)^H6 -> 0.88899636 | AH6: =MAX(Q6-AD6,0) -> 0 | AI6: =AG6*P6 -> 16256.823 | AJ6: =AG6*AC6 -> 9130.1283
A7: Chosen EV MSRP | B7: =IF('TCO Dashboard'!F29 = TRUE, 'TCO Dashboard'!E29,_xlfn.XLOOKUP('TCO Dashboard'!C19,EV_DB[Make & Model],EV_DB[Cost, $MSRP CAD])) -> 95833 | C7: $(CAD) | D7: EV database | E7: - | H7: 4 | I7: 0 | J7: =J6*(1+B$11) -> 6029.6403 | K7: =B20*B21*B40 -> 0 | L7: =L6*(1+B$16) -> 11142.684 | O7: =B55*B6 -> 1620 | P7: =SUM(I7:O7) -> 18792.324 | Q7: =Q6+P7 -> 126206.73 | R7: =($I$4-SUM($R$3:R6))*B$25 -> 4974.4125 | S7: 0 | T7: 0 | U7: =U6-(U6*B$48) -> -1417.476 | V7: =V6*(1+B$12) -> 1801.2687 | W7: =W6*(1+B$16) -> 5730.5232 | X7: 0 | Y7: =Y6+(1.02) -> 611.62286 | AB7: =B7*B54 -> 3833.32 | AC7: =SUM(S7:AB7) -> 10559.259 | AD7: =AD6+AC7 -> 141520.5 | AE7: =($S$4-SUM($AE$4:AE6))*B$26 -> 8828.0162 | AF7: =($B$37-SUM($AF$4:AF6))*IF('TCO Dashboard'!C$20 = 'Charger database'!A$6,B$28,B$27) -> 1900.9982 | AG7: =1/(1+$B$2)^H7 -> 0.85480419 | AH7: =MAX(Q7-AD7,0) -> 0 | AI7: =AG7*P7 -> 16063.758 | AJ7: =AG7*AC7 -> 9026.0986
A8: Fuel + electricity rates | B8: Value | C8: Unit | D8: Source | E8: Notes | H8: 5 | I8: 0 | J8: =J7*(1+B$11) -> 6331.1223 | K8: =B20*B21*B40 -> 0 | L8: =L7*(1+B$16) -> 11365.538 | O8: =B55*B6 -> 1620 | P8: =SUM(I8:O8) -> 19316.66 | Q8: =Q7+P8 -> 145523.39 | R8: =($I$4-SUM($R$3:R7))*B$25 -> 4228.2506 | S8: 0 | T8: 0 | U8: =U7-(U7*B$48) -> -1304.0779 | V8: =V7*(1+B$12) -> 1855.3067 | W8: =W7*(1+B$16) -> 5845.1337 | X8: 0 | Y8: =Y7+(1.02) -> 612.64286 | AB8: =B7*B54 -> 3833.32 | AC8: =SUM(S8:AB8) -> 10842.325 | AD8: =AD7+AC8 -> 152362.83 | AE8: =($S$4-SUM($AE$4:AE7))*B$26 -> 7503.8137 | AF8: =($B$37-SUM($AF$4:AF7))*IF('TCO Dashboard'!C$20 = 'Charger database'!A$6,B$28,B$27) -> 1330.6988 | AG8: =1/(1+$B$2)^H8 -> 0.82192711 | AH8: =MAX(Q8-AD8,0) -> 0 | AI8: =AG8*P8 -> 15876.886 | AJ8: =AG8*AC8 -> 8911.6011
A9: Diesel/ petrol cost ($/L) | B9: 1.459 | C9: $/L | E9: - | H9: 6 | I9: 0 | J9: =J8*(1+B$11) -> 6647.6784 | K9: =B20*B21*B40 -> 0 | L9: =L8*(1+B$16) -> 11592.848 | O9: =B55*B6 -> 1620 | P9: =SUM(I9:O9) -> 19860.527 | Q9: =Q8+P9 -> 165383.92 | R9: =($I$4-SUM($R$3:R8))*B$25 -> 3594.013 | S9: 0 | T9: 0 | U9: 0 | V9: =V8*(1+B$12) -> 1910.9659 | W9: =W8*(1+B$16) -> 5962.0363 | X9: 0 | Y9: =Y8+(1.02) -> 613.66286 | AB9: =B7*B54 -> 3833.32 | AC9: =SUM(S9:AB9) -> 12319.985 | AD9: =AD8+AC9 -> 164682.81 | AE9: =($S$4-SUM($AE$4:AE8))*B$26 -> 6378.2417 | AF9: =($B$37-SUM($AF$4:AF8))*IF('TCO Dashboard'!C$20 = 'Charger database'!A$6,B$28,B$27) -> 931.48914 | AG9: =1/(1+$B$2)^H9 -> 0.79031453 | AH9: =MAX(Q9-AD9,0) -> 701.10406 | AI9: =AG9*P9 -> 15696.063 | AJ9: =AG9*AC9 -> 9736.6632
A10: Energy charge($/kWh) | B10: =IF( 'TCO Dashboard'!F30 = TRUE, 'TCO Dashboard'!E30,_xlfn.XLOOKUP('TCO Dashboard'!F19,Fuelcosts_DB[Province],Fuelcosts_DB[Cost of electricity ($/kWh)])) -> 0.1784 | C10: $/kWh | D10: General Service Business Rates | E10: " - Revisit this cost | H10: 7 | I10: 0 | J10: =J9*(1+B$11) -> 6980.0624 | K10: =B20*B21*B40 -> 0 | L10: =L9*(1+B$16) -> 11824.705 | O10: =B55*B6 -> 1620 | P10: =SUM(I10:O10) -> 20424.768 | Q10: =Q9+P10 -> 185808.69 | R10: =($I$4-SUM($R$3:R9))*B$25 -> 3054.9111 | S10: 0 | T10: 0 | U10: 0 | V10: =V9*(1+B$12) -> 1968.2949 | W10: =W9*(1+B$16) -> 6081.2771 | X10: 0 | Y10: =Y9+(1.02) -> 614.68286 | AB10: =B7*B54 -> 3833.32 | AC10: =SUM(S10:AB10) -> 12497.575 | AD10: =AD9+AC10 -> 177180.39 | AE10: =($S$4-SUM($AE$4:AE9))*B$26 -> 5421.5054 | AF10: =($B$37-SUM($AF$4:AF9))*IF('TCO Dashboard'!C$20 = 'Charger database'!A$6,B$28,B$27) -> 652.0424 | AG10: =1/(1+$B$2)^H10 -> 0.75991781 | AH10: =MAX(Q10-AD10,0) -> 8628.297 | AI10: =AG10*P10 -> 15521.145 | AJ10: =AG10*AC10 -> 9497.1297
A11: Diesel/ Petrol annual price escalation | B11: =0.03+0.02 -> 0.05 | C11: % | D11: Up to 350 per cent higher at the pump by 2030: The impact of higher carbon taxes on gasoline prices - Canadian Energy Centre | E11: - Calculated the CAGR of 300% increase in 10 years | H11: Salvage year | M11: =-(I4-SUM(R3:R10)) -> -17311.163 | P11: =SUM(I11:O11) -> -17311.163 | Q11: =Q10+P11 -> 168497.52 | Z11: =-(S4-SUM(AE4:AE10)) -> -30721.864 | AA11: =-(B37-SUM(AF4:AF10)) -> -1521.4323 | AC11: =SUM(S11:AB11) -> -32243.296 | AD11: =AD10+AC11 -> 144937.09 | AG11: =1/(1+$B$2)^8 -> 0.73069021 | AH11: =MAX(Q11-AD11,0) -> 23560.431 | AI11: =AG11*P11 -> -12649.097 | AJ11: =AG11*AC11 -> -23559.861
A12: Energy annual price escalation | B12: 0.03 | C12: % | D12: BC Gov News | H12: Total Cost | I12: =SUM(I4:I11) -> 54000 | J12: =SUM(J3:J11) -> 42408.709 | K12: =SUM(K3:K11) -> 0 | L12: =SUM(L3:L11) -> 78059.976 | M12: =SUM(M3:M11) -> -17311.163 | O12: =SUM(O3:O11) -> 11340 | P12: =SUM(P3:P11) -> 168497.52 | R12: =SUM(R3:R11) -> 36688.837 | S12: =SUM(S4:S11) -> 95833 | T12: =SUM(T4:T11) -> -10000 | U12: =SUM(U3:U11) -> -7757.3392 | V12: =SUM(V3:V11) -> 12630.925 | W12: =SUM(W3:W11) -> 40145.13 | X12: =SUM(X4:X11) -> 15214.072 | Y12: =SUM(Y3:Y11) -> 4281.36 | Z12: =SUM(Z3:Z11) -> -30721.864 | AA12: =SUM(AA3:AA11) -> -1521.4323 | AB12: =SUM(AB3:AB11) -> 26833.24 | AC12: =SUM(AC3:AC11) -> 144937.09 | AE12: =SUM(AE3:AE11) -> 65111.136 | AF12: =SUM(AF3:AF11) -> 13692.639
A13: Maintenance costs | B13: Value | C13: Unit | D13: Source | E13: Notes | H13: Total PV cost | I13: =SUMPRODUCT(I4:I11,$AG3:$AG11) -> #VALUE! | J13: =SUMPRODUCT(J3:J11,$AG3:$AG11) -> 36085.741 | K13: =SUMPRODUCT(K3:K11,$AG3:$AG11) -> 0 | L13: =SUMPRODUCT(L3:L11,$AG3:$AG11) -> 66723.982 | M13: =SUMPRODUCT(M3:M11,$AG3:$AG11) -> -12649.097 | O13: =SUMPRODUCT(O3:O11,$AG3:$AG11) -> 9723.3286 | P13: =SUMPRODUCT(P3:P11,$AG3:$AG11) -> 151807.03 | R13: =SUMPRODUCT(R3:R11,$AG3:$AG11) -> 32246.005 | S13: =SUMPRODUCT(S4:S11,$AG3:$AG11) -> #VALUE! | T13: =SUMPRODUCT(T4:T11,$AG3:$AG11) -> #VALUE! | U13: =SUMPRODUCT(U3:U11,$AG3:$AG11) -> -6951.9199 | V13: =SUMPRODUCT(V3:V11,$AG3:$AG11) -> 10780.137 | W13: =SUMPRODUCT(W3:W11,$AG3:$AG11) -> 34315.191 | X13: =SUMPRODUCT(X4:X11,$AG4:$AG11) -> 14628.915 | Y13: =SUMPRODUCT(Y3:Y11,$AG3:$AG11) -> 3670.0346 | Z13: =SUMPRODUCT(Z3:Z11,$AG3:$AG11) -> -22448.165 | AB13: =SUMPRODUCT(AB3:AB11,$AG3:$AG11) -> 23007.796 | AC13: =SUMPRODUCT(AC3:AC11,$AG3:$AG11) -> 138422.02 | AE13: =SUMPRODUCT(AE3:AE11,$AG3:$AG11) -> 57226.506 | AF13: =SUMPRODUCT(AF3:AF11,$AG3:$AG11) -> 12145.879 | AI13: =SUM(AI3:AI11) -> 151807.03 | AJ13: =SUM(AJ3:AJ11) -> 138422.02
A14: ICE maintenance costs | B14: =IF('TCO Dashboard'!D28 = TRUE,('TCO Dashboard'!C28/'TCO Dashboard'!F20),_xlfn.XLOOKUP('TCO Dashboard'!C21,ICE_DB[Make + Model],ICE_DB[Maintenance cost ($/km)])) -> 0.35 | C14: $/km | D14: internal estimate | E14: -
A15: EV maintenance cost | B15: =IF('TCO Dashboard'!F28 = TRUE, ('TCO Dashboard'!E28/'TCO Dashboard'!F20),_xlfn.XLOOKUP('TCO Dashboard'!C19,EV_DB[Make & Model],EV_DB[Maintenance cost ($/km)])) -> 0.18 | C15: $/km | D15: EV database | E15: -
A16: Maintenance costs escalation | B16: 0.02 | C16: % | D16: Internal estimate | E16: -
A17: Charging infastructure maintenance costs | B17: 0.04 | C17: % | D17: internal estimate
A18: Vehicle efficiency & Duty cycle | B18: Value | C18: Unit | D18: Source | E18: Notes
A19: EV efficiency | B19: =_xlfn.XLOOKUP('TCO Dashboard'!C19,EV_DB[Make & Model],EV_DB[Efficiency (kwh/km)]) -> 0.308 | C19: kWh/km | D19: EV database | E19: - | H19: Scenario 2: Finance vehicles + Purchase chargers upfront
A20: ICE efficiency (L/km) | B20: =_xlfn.XLOOKUP('TCO Dashboard'!C21,ICE_DB[Make + Model],ICE_DB[Efficiency (L/KM)]) -> 0.119 | C20: L/km | D20: ICE database | E20: - | H20: Year | I20: ICE - Down payment | J20: ICE - Annualized monthly payments | K20: ICE - Fuel cost | L20: ICE - Carbon tax | M20: ICE - Tires & Maintenance cost | N20: ICE - salvage value | P20: ICE - vehicle insurance | Q20: ICE - Total cost | R20: ICE - Cumulative Total Cost | S20: ICE- depreciation | T20: EV - Down Payment | U20: EV - Annualized monthly payments | V20: EV - Vehicle Rebate | W20: EV - CFR/LCFS | X20: EV - Charging cost | Y20: EV - Tires & Maintenance Cost | Z20: EV - Charging infrastructure cost | AA20: EV - Charging infrastructure Rebate | AB20: EV - Charger infrastructure maintenance | AC20: EV - Salvage value | AD20: EV - Charger Salvage value | AE20: EV- vehicle insurance | AF20: EV -Total cost | AG20: EV - Cumulative Total Cost | AH20: EV - depreciation | AI20: Chargers - depreciation | AJ20: Discount Factor | AK20: ICE -Total discounted cost | AL20: EV - Total discounted cost | AM20: Cumulative Savings
A21: Annual vehicle KM travelled | B21: =IF(ISBLANK('TCO Dashboard'!F20), 10000,'TCO Dashboard'!F20) -> 30000 | C21: km | D21: Input | E21: - | H21: 0 | K21: 0 | M21: 0 | Q21: =SUM(I21:P21) -> 0 | R21: =Q21 -> 0 | S21: 0 | X21: 0 | Y21: 0 | AA21: =-B52 -> 0 | AF21: =SUM(T21:AE21) -> 0 | AG21: =AF21 -> 0 | AH21: 0 | AI21: 0 | AJ21: =1 -> 1 | AK21: =AJ21*Q21 -> 0 | AL21: =AJ21*AF21 -> 0 | AM21: =MAX(R21-AG21,0) -> 0
A22: Average lifespan | B22: 10 | C22: years | D22: Don't forget the little guys - Truck News | E22: - | H22: 1 | I22: =B30*B6 -> 2700 | J22: =PMT((B31/12),(B32*12),-(B6-(B6*B30)))*12 -> 9291.0538 | K22: =(B$20*B$21)*B$9 -> 5208.63 | L22: =B20*B21*B40 -> 0 | M22: =B14*B21 -> 10500 | P22: =B55*B6 -> 1620 | Q22: =SUM(I22:P22) -> 29319.684 | R22: =R21+Q22 -> 29319.684 | S22: =($B$6-SUM($S$21:S21))*B$25*0.5 -> 4050 | T22: =B33*B7 -> 4791.65 | U22: =PMT((B34/12),(B35*12),-(B7-(B7*B33)-B$50))*12 -> 14677.574 | V22: =-B50 -> -10000 | W22: =-B41-B43 -> -1820.3388 | X22: =(B$19*B$10)*B$21 -> 1648.416 | Y22: =B$15*B$21 -> 5400 | Z22: =B37*B38 -> 15214.072 | AA22: 0 | AB22: =Z22*B17 -> 608.56286 | AE22: =B7*B54 -> 3833.32 | AF22: =SUM(T22:AE22)-V22 -> 44353.256 | AG22: =AG21+AF22 -> 44353.256 | AH22: =($B$7-SUM($AH$21:AH21))*B$26*0.5 -> 7187.475 | AI22: =0.5*($B$37)*IF('TCO Dashboard'!C20 = 'Charger database'!A6,B$28,B$27) -> 2282.1107 | AJ22: =1/(1+$B$2)^H22 -> 0.96153846 | AK22: =AJ22*Q22 -> 28192.004 | AL22: =AJ22*AF22 -> 42647.361 | AM22: =MAX(R22-AG22,0) -> 0
A23: operational days/ year | B23: 260 | C23: days | D23: Input | E23: - | H23: 2 | J23: =PMT((B31/12),(B32*12),-(B6-(B6*B30)))*12 -> 9291.0538 | K23: =K22*(1+B$11) -> 5469.0615 | L23: =B20*B21*B40 -> 0 | M23: =M22*(1+B$16) -> 10710 | P23: =B55*B6 -> 1620 | Q23: =SUM(I23:P23) -> 27090.115 | R23: =R22+Q23 -> 56409.799 | S23: =($B$6-SUM($S$21:S22))*B$25 -> 7492.5 | T23: 0 | U23: =PMT((B34/12),(B35*12),-(B7-(B7*B33)-B$50))*12 -> 14677.574 | V23: 0 | W23: =W22-(W22*B$48) -> -1674.7117 | X23: =X22*(1+B$12) -> 1697.8685 | Y23: =Y22*(1+B$16) -> 5508 | Z23: 0 | AA23: 0 | AB23: =AB22+(1.02) -> 609.58286 | AE23: =B7*B54 -> 3833.32 | AF23: =SUM(T23:AE23) -> 24651.634 | AG23: =AG22+AF23 -> 69004.889 | AH23: =($B$7-SUM($AH$21:AH22))*B$26 -> 13296.829 | AI23: =($B$37-SUM($AI22:AI$22))*IF('TCO Dashboard'!C$20 = 'Charger database'!A$6,B$28,B$27) -> 3879.5883 | AJ23: =1/(1+$B$2)^H23 -> 0.92455621 | AK23: =AJ23*Q23 -> 25046.334 | AL23: =AJ23*AF23 -> 22791.821 | AM23: =MAX(R23-AG23,0) -> 0
A24: Depreciation rates | B24: Value | C24: Unit | D24: Source | E24: Notes | H24: 3 | J24: =PMT((B31/12),(B32*12),-(B6-(B6*B30)))*12 -> 9291.0538 | K24: =K23*(1+B$11) -> 5742.5146 | L24: =B20*B21*B40 -> 0 | M24: =M23*(1+B$16) -> 10924.2 | P24: =B55*B6 -> 1620 | Q24: =SUM(I24:P24) -> 27577.768 | R24: =R23+Q24 -> 83987.567 | S24: =($B$6-SUM($S$21:S23))*B$25 -> 6368.625 | T24: 0 | U24: =PMT((B34/12),(B35*12),-(B7-(B7*B33)-B$50))*12 -> 14677.574 | V24: 0 | W24: =W23-(W23*B$48) -> -1540.7348 | X24: =X23*(1+B$12) -> 1748.8045 | Y24: =Y23*(1+B$16) -> 5618.16 | Z24: 0 | AA24: 0 | AB24: =AB23+(1.02) -> 610.60286 | AE24: =B7*B54 -> 3833.32 | AF24: =SUM(T24:AE24) -> 24947.727 | AG24: =AG23+AF24 -> 93952.616 | AH24: =($B$7-SUM($AH$21:AH23))*B$26 -> 11302.304 | AI24: =($B$37-SUM($AI$22:AI23))*IF('TCO Dashboard'!C$20 = 'Charger database'!A$6,B$28,B$27) -> 2715.7118 | AJ24: =1/(1+$B$2)^H24 -> 0.88899636 | AK24: =AJ24*Q24 -> 24516.536 | AL24: =AJ24*AF24 -> 22178.438 | AM24: =MAX(R24-AG24,0) -> 0
A25: ICE annual declining depreciation rate | B25: =0.15 -> 0.15 | C25: % | D25: Estimation | E25: Low mileage used compared to other trucks, 260 operational days out of a year | H25: 4 | J25: =PMT((B31/12),(B32*12),-(B6-(B6*B30)))*12 -> 9291.0538 | K25: =K24*(1+B$11) -> 6029.6403 | L25: =B20*B21*B40 -> 0 | M25: =M24*(1+B$16) -> 11142.684 | P25: =B55*B6 -> 1620 | Q25: =SUM(I25:P25) -> 28083.378 | R25: =R24+Q25 -> 112070.95 | S25: =($B$6-SUM($S$21:S24))*B$25 -> 5413.3313 | T25: 0 | U25: =PMT((B34/12),(B35*12),-(B7-(B7*B33)-B$50))*12 -> 14677.574 | V25: 0 | W25: =W24-(W24*B$48) -> -1417.476 | X25: =X24*(1+B$12) -> 1801.2687 | Y25: =Y24*(1+B$16) -> 5730.5232 | Z25: 0 | AA25: 0 | AB25: =AB24+(1.02) -> 611.62286 | AE25: =B7*B54 -> 3833.32 | AF25: =SUM(T25:AE25) -> 25236.833 | AG25: =AG24+AF25 -> 119189.45 | AH25: =($B$7-SUM($AH$21:AH24))*B$26 -> 9606.9588 | AI25: =($B$37-SUM($AI$22:AI24))*IF('TCO Dashboard'!C$20 = 'Charger database'!A$6,B$28,B$27) -> 1900.9982 | AJ25: =1/(1+$B$2)^H25 -> 0.85480419 | AK25: =AJ25*Q25 -> 24005.789 | AL25: =AJ25*AF25 -> 21572.55 | AM25: =MAX(R25-AG25,0) -> 0
A26: EV annual declining depreciation rate | B26: 0.15 | C26: % | D26: Estimation | E26: Low mileage, less strain on the battery than expected | H26: 5 | J26: =PMT((B31/12),(B32*12),-(B6-(B6*B30)))*12 -> 9291.0538 | K26: =K25*(1+B$11) -> 6331.1223 | L26: =B20*B21*B40 -> 0 | M26: =M25*(1+B$16) -> 11365.538 | P26: =B55*B6 -> 1620 | Q26: =SUM(I26:P26) -> 28607.714 | R26: =R25+Q26 -> 140678.66 | S26: =($B$6-SUM($S$21:S25))*B$25 -> 4601.3316 | T26: 0 | U26: =PMT((B34/12),(B35*12),-(B7-(B7*B33)-B$50))*12 -> 14677.574 | V26: 0 | W26: =W25-(W25*B$48) -> -1304.0779 | X26: =X25*(1+B$12) -> 1855.3067 | Y26: =Y25*(1+B$16) -> 5845.1337 | Z26: 0 | AA26: 0 | AB26: =AB25+(1.02) -> 612.64286 | AE26: =B7*B54 -> 3833.32 | AF26: =SUM(T26:AE26) -> 25519.899 | AG26: =AG25+AF26 -> 144709.35 | AH26: =($B$7-SUM($AH$21:AH25))*B$26 -> 8165.915 | AI26: =($B$37-SUM($AI$22:AI25))*IF('TCO Dashboard'!C$20 = 'Charger database'!A$6,B$28,B$27) -> 1330.6988 | AJ26: =1/(1+$B$2)^H26 -> 0.82192711 | AK26: =AJ26*Q26 -> 23513.455 | AL26: =AJ26*AF26 -> 20975.497 | AM26: =MAX(R26-AG26,0) -> 0
A27: Class 43.1 CCA Chargers annual declining depreciation rate | B27: 0.3 | C27: % | D27: Estimation | E27: Capital Cost Allowance (CCA) and CCA Classes | H27: 6 | J27: =PMT((B31/12),(B32*12),-(B6-(B6*B30)))*12 -> 9291.0538 | K27: =K26*(1+B$11) -> 6647.6784 | L27: =B20*B21*B40 -> 0 | M27: =M26*(1+B$16) -> 11592.848 | P27: =B55*B6 -> 1620 | Q27: =SUM(I27:P27) -> 29151.581 | R27: =R26+Q27 -> 169830.24 | S27: =($B$6-SUM($S$21:S26))*B$25 -> 3911.1318 | T27: 0 | U27: =PMT((B34/12),(B35*12),-(B7-(B7*B33)-B$50))*12 -> 14677.574 | V27: 0 | W27: 0 | X27: =X26*(1+B$12) -> 1910.9659 | Y27: =Y26*(1+B$16) -> 5962.0363 | Z27: 0 | AA27: 0 | AB27: =AB26+(1.02) -> 613.66286 | AE27: =B7*B54 -> 3833.32 | AF27: =SUM(T27:AE27) -> 26997.559 | AG27: =AG26+AF27 -> 171706.91 | AH27: =($B$7-SUM($AH$21:AH26))*B$26 -> 6941.0277 | AI27: =($B$37-SUM($AI$22:AI26))*IF('TCO Dashboard'!C$20 = 'Charger database'!A$6,B$28,B$27) -> 931.48914 | AJ27: =1/(1+$B$2)^H27 -> 0.79031453 | AK27: =AJ27*Q27 -> 23038.918 | AL27: =AJ27*AF27 -> 21336.563 | AM27: =MAX(R27-AG27,0) -> 0
A28: Class 43.2 CCA Chargers annual declining depreciation rate | B28: 0.5 | C28: % | D28: Estimation | E28: https://www.csagroup.org/standards/areas-of-focus/fuels-transportation/standards-for-battery-electric-vehicles-and-energy-management/ | H28: 7 | J28: =PMT((B31/12),(B32*12),-(B6-(B6*B30)))*12 -> 9291.0538 | K28: =K27*(1+B$11) -> 6980.0624 | L28: =B20*B21*B40 -> 0 | M28: =M27*(1+B$16) -> 11824.705 | P28: =B55*B6 -> 1620 | Q28: =SUM(I28:P28) -> 29715.822 | R28: =R27+Q28 -> 199546.06 | S28: =($B$6-SUM($S$21:S27))*B$25 -> 3324.4621 | T28: 0 | U28: =PMT((B34/12),(B35*12),-(B7-(B7*B33)-B$50))*12 -> 14677.574 | V28: 0 | W28: 0 | X28: =X27*(1+B$12) -> 1968.2949 | Y28: =Y27*(1+B$16) -> 6081.2771 | Z28: 0 | AA28: 0 | AB28: =AB27+(1.02) -> 614.68286 | AE28: =B7*B54 -> 3833.32 | AF28: =SUM(T28:AE28) -> 27175.149 | AG28: =AG27+AF28 -> 198882.06 | AH28: =($B$7-SUM($AH$21:AH27))*B$26 -> 5899.8736 | AI28: =($B$37-SUM($AI$22:AI27))*IF('TCO Dashboard'!C$20 = 'Charger database'!A$6,B$28,B$27) -> 652.0424 | AJ28: =1/(1+$B$2)^H28 -> 0.75991781 | AK28: =AJ28*Q28 -> 22581.582 | AL28: =AJ28*AF28 -> 20650.88 | AM28: =MAX(R28-AG28,0) -> 664.00605
A29: Financing terms | B29: Value | C29: Unit | D29: Source | E29: Notes | H29: Salvage year | N29: =-(B6-SUM(S21:S28)) -> -18838.618 | Q29: =SUM(I29:P29) -> -18838.618 | R29: =R28+Q29 -> 180707.44 | AC29: =-(B7-SUM(AH22:AH28)) -> -33432.617 | AD29: =-(B37-SUM(AI22:AI28)) -> -1521.4323 | AF29: =SUM(T29:AE29) -> -34954.049 | AG29: =AG28+AF29 -> 163928.01 | AJ29: =1/(1+$B$2)^11 -> 0.64958093 | AK29: =AJ29*Q29 -> -12237.207 | AL29: =AJ29*AF29 -> -22705.484 | AM29: =MAX(R29-AG29,0) -> 16779.437
A30: ICE vehicle down payment as % of MSRP | B30: ='TCO Dashboard'!K19 -> 0.05 | C30: % | E30: - | H30: Total Cost | I30: =SUM(I22:I29) -> 2700 | J30: =SUM(J21:J29) -> 65037.377 | K30: =SUM(K21:K29) -> 42408.709 | L30: =SUM(L21:L29) -> 0 | M30: =SUM(M21:M29) -> 78059.976 | N30: =SUM(N21:N29) -> -18838.618 | P30: =SUM(P21:P29) -> 11340 | Q30: =SUM(Q21:Q29) -> 180707.44 | S30: =SUM(S21:S29) -> 35161.382 | T30: =SUM(T22:T29) -> 4791.65 | U30: =SUM(U21:U29) -> 102743.02 | V30: =SUM(V22:V29) -> -10000 | W30: =SUM(W21:W29) -> -7757.3392 | X30: =SUM(X21:X29) -> 12630.925 | Y30: =SUM(Y21:Y29) -> 40145.13 | Z30: =SUM(Z22:Z29) -> 15214.072 | AA30: =SUM(AA21:AA29) -> 0 | AB30: =SUM(AB21:AB29) -> 4281.36 | AC30: =SUM(AC21:AC29) -> -33432.617 | AD30: =SUM(AD21:AD29) -> -1521.4323 | AE30: =SUM(AE21:AE29) -> 26833.24 | AF30: =SUM(AF21:AF29) -> 163928.01 | AH30: =SUM(AH21:AH29) -> 62400.383 | AI30: =SUM(AI21:AI29) -> 13692.639
A31: ICE vehicle loan interest rate | B31: ='TCO Dashboard'!K20 -> 0.07 | C31: % | E31: - | H31: Total PV cost | I31: =SUMPRODUCT(I22:I29,$AJ21:$AJ29) -> #VALUE! | J31: =SUMPRODUCT(J21:J29,$AJ21:$AJ29) -> 55765.413 | K31: =SUMPRODUCT(K21:K29,$AJ21:$AJ29) -> 36085.741 | L31: =SUMPRODUCT(L21:L29,$AJ21:$AJ29) -> 0 | M31: =SUMPRODUCT(M21:M29,$AJ21:$AJ29) -> 66723.982 | N31: =SUMPRODUCT(N21:N29,$AJ21:$AJ29) -> -12237.207 | P31: =SUMPRODUCT(P21:P29,$AJ21:$AJ29) -> 9723.3286 | Q31: =SUMPRODUCT(Q21:Q29,$AJ21:$AJ29) -> 158657.41 | S31: =SUMPRODUCT(S21:S29,$AJ21:$AJ29) -> 30509.792 | T31: =SUMPRODUCT(T22:T29,$AJ21:$AJ29) -> #VALUE! | U31: =SUMPRODUCT(U21:U29,$AJ21:$AJ29) -> 88095.601 | V31: =SUMPRODUCT(V22:V29,$AJ21:$AJ29) -> #VALUE! | W31: =SUMPRODUCT(W21:W29,$AJ21:$AJ29) -> -6951.9199 | X31: =SUMPRODUCT(X21:X29,$AJ21:$AJ29) -> 10780.137 | Y31: =SUMPRODUCT(Y21:Y29,$AJ21:$AJ29) -> 34315.191 | Z31: =SUMPRODUCT(Z22:Z29,$AJ21:$AJ29) -> #VALUE! | AA31: =SUMPRODUCT(AA21:AA29,$AJ21:$AJ29) -> 0 | AB31: =SUMPRODUCT(AB21:AB29,$AJ21:$AJ29) -> 3670.0346 | AC31: =SUMPRODUCT(AC21:AC29,$AJ21:$AJ29) -> -21717.19 | AE31: =SUMPRODUCT(AE21:AE29,$AJ21:$AJ29) -> 23007.796 | AF31: =SUMPRODUCT(AF21:AF29,$AJ21:$AJ29) -> 149447.63 | AH31: =SUMPRODUCT(AH21:AH29,$AJ21:$AJ29) -> 54145.276 | AI31: =SUMPRODUCT(AI21:AI29,$AJ21:$AJ29) -> 12145.879 | AK31: =SUM(AK21:AK29) -> 158657.41 | AL31: =SUM(AL21:AL29) -> 149447.63
A32: ICE vehicle loan term (years) | B32: ='TCO Dashboard'!K21 -> 7 | C32: years
A33: EV down payment as % of MSRP | B33: ='TCO Dashboard'!K22 -> 0.05 | C33: % | E33: -
A34: EV loan interest rate | B34: ='TCO Dashboard'!K23 -> 0.07 | C34: % | E34: -
A35: EV loan term (years) | B35: ='TCO Dashboard'!K24 -> 7 | C35: years
A36: Charging Infrastructure | B36: Value | C36: Unit | D36: Source | E36: Notes | H36: Scenario 3: Finance Vehicles + Charging as a service
A37: Charging station hardware+ installation cost | B37: =IF('TCO Dashboard'!F31=TRUE, 'TCO Dashboard'!E31,_xlfn.XLOOKUP('TCO Dashboard'!C20,Charger_DB[Charger type],Charger_DB[Purchase + installation cost$ CAD])) -> 15214.072 | C37: $(CAD)/ charger | D37: Internal costing | E37: - | H37: Year | I37: ICE - Down payment | J37: ICE - Annualized monthly payments | K37: ICE - Fuel cost | L37: ICE - Carbon tax | M37: ICE - Tires & Maintenance cost | N37: ICE - salvage value | P37: ICE - vehicle insurance | Q37: ICE - Total cost | R37: ICE - Cumulative Total Cost | S37: ICE- depreciation | T37: EV - Down Payment | U37: EV - Annualized monthly payments | V37: EV - Vehicle Rebate | W37: EV - CFR/LCFS | X37: EV - Charging cost | Y37: EV - Tires & Maintenance Cost | Z37: EV - Charging as a service | AA37: EV - Charging Infrastructure Rebate | AC37: EV - Vehicle Salvage value | AD37: EV - Charger Salvage value | AE37: EV- vehicle insurance | AF37: EV -Total cost | AG37: EV - Cumulative Total Cost | AH37: EV - depreciation | AI37: Chargers - depreciation | AJ37: Discount Factor | AK37: ICE -Total discounted cost | AL37: EV - Total discounted cost | AM37: Cumulative Savings
A38: Charger cost assignment | B38: =1/'TCO Dashboard'!F21 -> 1 | C38: % | D38: Decided value | E38: " one charger will serve X trucks" | H38: 0 | K38: 0 | M38: 0 | Q38: =SUM(I38:P38) -> 0 | R38: =Q38 -> 0 | S38: 0 | X38: 0 | Y38: 0 | AF38: =SUM(T38:AE38) -> 0 | AG38: =AF38 -> 0 | AH38: 0 | AI38: 0 | AJ38: =1 -> 1 | AK38: =AJ38*Q38 -> 0 | AL38: =AJ38*AF38 -> 0 | AM38: =MAX(R38-AG38,0) -> 0
A39: Taxes & Credits | B39: Value | C39: Unit | D39: Source | E39: Notes | H39: 1 | I39: =B30*B6 -> 2700 | J39: =PMT((B31/12),(B32*12),-(B6-(B6*B30)))*12 -> 9291.0538 | K39: =(B$20*B$21)*B$9 -> 5208.63 | L39: =B20*B21*B40 -> 0 | M39: =B14*B21 -> 10500 | P39: =B55*B6 -> 1620 | Q39: =SUM(I39:P39) -> 29319.684 | R39: =R38+Q39 -> 29319.684 | S39: =($B$6-SUM($S$38:S38))*B$25 -> 8100 | T39: =B33*B7 -> 4791.65 | U39: =PMT((B34/12),(B35*12),-(B7-(B7*B33)-B$50))*12 -> 14677.574 | V39: =-B50 -> -10000 | W39: =-B41-B43 -> -1820.3388 | X39: =(B$19*B$10)*B$21 -> 1648.416 | Y39: =B$15*B$21 -> 5400 | Z39: =(((B37*B38)-B52)*1.8)/7 -> 3912.1898 | AA39: =-B52 -> 0 | AE39: =B7*B54 -> 3833.32 | AF39: =SUM(T39:AE39)-V39-AA39 -> 32442.811 | AG39: =AG38+AF39 -> 32442.811 | AH39: =($B$7-SUM($AH$38:AH38))*B$26*0.5 -> 7187.475 | AI39: =0.5*($B$37)*IF('TCO Dashboard'!C20 = 'Charger database'!A$6,B$28,B$27) -> 2282.1107 | AJ39: =1/(1+$B$2)^H39 -> 0.96153846 | AK39: =AJ39*Q39 -> 28192.004 | AL39: =AJ39*AF39 -> 31195.011 | AM39: =MAX(R39-AG39,0) -> 0
A40: Carbon tax | B40: 0 | C40: $/L | D40: Carbon tax rates by fuel type - Province of British Columbia | E40: - | H40: 2 | J40: =PMT((B31/12),(B32*12),-(B6-(B6*B30)))*12 -> 9291.0538 | K40: =K39*(1+B$11) -> 5469.0615 | L40: =B20*B21*B40 -> 0 | M40: =M39*(1+B$16) -> 10710 | P40: =B55*B6 -> 1620 | Q40: =SUM(I40:P40) -> 27090.115 | R40: =R39+Q40 -> 56409.799 | S40: =($B$6-SUM($S$38:S39))*B$25 -> 6885 | T40: 0 | U40: =PMT((B34/12),(B35*12),-(B7-(B7*B33)-B$50))*12 -> 14677.574 | W40: =W39-(W39*B$48) -> -1674.7117 | X40: =X39*(1+B$12) -> 1697.8685 | Y40: =Y39*(1+B$16) -> 5508 | Z40: =(((B37*B38)-B52)*1.8)/7 -> 3912.1898 | AE40: =B7*B54 -> 3833.32 | AF40: =SUM(T40:AE40) -> 27954.241 | AG40: =AG39+AF40 -> 60397.052 | AH40: =($B$7-SUM($AH$38:AH39))*B$26 -> 13296.829 | AI40: =($B$37-SUM($AI$39:AI39))*IF('TCO Dashboard'!C$20 = 'Charger database'!A$6,B$28,B$27) -> 3879.5883 | AJ40: =1/(1+$B$2)^H40 -> 0.92455621 | AK40: =AJ40*Q40 -> 25046.334 | AL40: =AJ40*AF40 -> 25845.267 | AM40: =MAX(R40-AG40,0) -> 0
...

Sheet EV database
A1: Manufacturer | B1: Model | C1: Make & Model | D1: Type/Use Case | E1: Model Year | F1: FHWA Class (2B - 8) | G1: Category | H1: GVWR, lbs. (Gross Vehicle Weight Rating) | I1: Max Payload, lbs. | J1: Cost, $MSRP CAD | K1: Maintenance cost ($/km) | L1: Refrigerated Unit | M1: Battery Size, kWh | N1: Efficiency (kwh/km) | O1: Max Charge Rate, kw | P1: Battery Voltage (V) | Q1: Range (km) | R1: Federal Rebates (iMHZEV) | S1: ON Vehicle Rebates | T1: BC Vehicle Rebates | U1: QC Vehicle Rebates | V1: AB Vehicle Rebates | W1: SC Vehicle Rebates | X1: NS Vehicle Rebates | Y1: NB Vehicle Rebates | Z1: MB Vehicle Rebates | AA1: PEI Vehicle Rebates | AB1: NL Vehicle Rebates | AC1: YT Vehicle Rebates | AD1: NU Vehicle Rebates | AE1: NT Vehicle Rebates | AF1: ON - Total rebate(s) value | AG1: BC - Total rebate(s) value | AH1: QC - Total rebate(s) value | AI1: AB - Total rebate(s) value | AJ1: SC - Total rebate(s) value | AK1: NS - Total rebate(s) value | AL1: NB - Total rebate(s) value | AM1: MB - Total rebate(s) value | AN1: PEI - Total rebate(s) value | AO1: NL - Total rebate(s) value | AP1: YT - Total rebate(s) value | AQ1: NU - Total rebate(s) value | AR1: NT - Total rebate(s) value
A2: Ram | B2: Electric 1500 Large Battery | C2: =EV_DB[[#This Row],[Manufacturer ]]& " " &EV_DB[[#This Row],[Model]] -> Ram Electric 1500 Large Battery | D2: Pick-up truck | E2: 2025 | F2: 2B | G2: {=_xlfn.IFS(OR(EV_DB[[#This Row],[FHWA Class (2B - 8)]]= "2B", EV_DB[[#This Row],[FHWA Class (2B - 8)]]=3), "Light Duty",OR(EV_DB[[#This Row],[FHWA Class (2B - 8)]]=4,EV_DB[[#This Row],[FHWA Class (2B - 8)]]=5,EV_DB[[#This Row],[FHWA Class (2B - 8)]]=6),"Medium Duty",OR(EV_DB[[#This Row],[FHWA Class (2B - 8)]]=7,EV_DB[[#This Row],[FHWA Class (2B - 8)]]=8), "Heavy Duty")} -> Light Duty | H2: 7,800 | I2: 1700 | J2: 81085 | K2: {=_xlfn.IFS(EV_DB[[#This Row],[Category]]="Light Duty",'Maintenance costs table'!$D$4,EV_DB[[#This Row],[Category]]="Medium Duty",'Maintenance costs table'!$D$8,EV_DB[[#This Row],[Category]]="Heavy Duty",'Maintenance costs table'!$D$6)} -> 0.18 | L2: No | M2: 229kwh | N2: 0.29 | Q2: 800 | R2: {=_xlfn.IFS(EV_DB[[#This Row],[Battery Size, kWh]]>350 & EV_DB[[#This Row],[FHWA Class (2B - 8)]]=8,'iMHZEV table'!$D$4,EV_DB[[#This Row],[Battery Size, kWh]]<=350 & EV_DB[[#This Row],[FHWA Class (2B - 8)]]=8,'iMHZEV table'!$D$5, TRUE, _xlfn.XLOOKUP(EV_DB[[#This Row],[FHWA Class (2B - 8)]],'iMHZEV table'!$A$3:$A$11,'iMHZEV table'!$D$3:$D$11))} -> 10000 | T2: {=_xlfn.IFS(EV_DB[[#This Row],[FHWA Class (2B - 8)]]= "2B",10000,EV_DB[[#This Row],[FHWA Class (2B - 8)]]=3,55000,OR(EV_DB[[#This Row],[FHWA Class (2B - 8)]]=4,EV_DB[[#This Row],[FHWA Class (2B - 8)]]=5), 75000,OR(EV_DB[[#This Row],[FHWA Class (2B - 8)]]=6,EV_DB[[#This Row],[FHWA Class (2B - 8)]]=7),100000,EV_DB[[#This Row],[FHWA Class (2B - 8)]]=8, 150000)} -> 10000 | AF2: =MIN(MAX(EV_DB[[#This Row],[Federal Rebates (iMHZEV) ]],EV_DB[[#This Row],[ON Vehicle Rebates]]),PRODUCT(EV_DB[[#This Row],[Cost, $MSRP CAD]],0.75)) -> 10000 | AG2: =MIN(EV_DB[[#This Row],[Federal Rebates (iMHZEV) ]]+EV_DB[[#This Row],[BC Vehicle Rebates]],PRODUCT(EV_DB[[#This Row],[Cost, $MSRP CAD]],0.75)) -> 20000 | AH2: =MIN(EV_DB[[#This Row],[Federal Rebates (iMHZEV) ]]+EV_DB[[#This Row],[QC Vehicle Rebates]],PRODUCT(EV_DB[[#This Row],[Cost, $MSRP CAD]],0.75)) -> 10000 | AI2: =MIN(MAX(EV_DB[[#This Row],[Federal Rebates (iMHZEV) ]],EV_DB[[#This Row],[AB Vehicle Rebates]]),PRODUCT(EV_DB[[#This Row],[Cost, $MSRP CAD]],0.75)) -> 10000 | AJ2: =MIN(MAX(EV_DB[[#This Row],[Federal Rebates (iMHZEV) ]],EV_DB[[#This Row],[SC Vehicle Rebates]]),PRODUCT(EV_DB[[#This Row],[Cost, $MSRP CAD]],0.75)) -> 10000 | AK2: =MIN(MAX(EV_DB[[#This Row],[Federal Rebates (iMHZEV) ]],EV_DB[[#This Row],[NS Vehicle Rebates]]),PRODUCT(EV_DB[[#This Row],[Cost, $MSRP CAD]],0.75)) -> 10000 | AL2: =MIN(MAX(EV_DB[[#This Row],[Federal Rebates (iMHZEV) ]],EV_DB[[#This Row],[NB Vehicle Rebates]]),PRODUCT(EV_DB[[#This Row],[Cost, $MSRP CAD]],0.75)) -> 10000 | AM2: =MIN(MAX(EV_DB[[#This Row],[Federal Rebates (iMHZEV) ]],EV_DB[[#This Row],[MB Vehicle Rebates]]),PRODUCT(EV_DB[[#This Row],[Cost, $MSRP CAD]],0.75)) -> 10000 | AN2: =MIN(MAX(EV_DB[[#This Row],[Federal Rebates (iMHZEV) ]],EV_DB[[#This Row],[PEI Vehicle Rebates]]),PRODUCT(EV_DB[[#This Row],[Cost, $MSRP CAD]],0.75)) -> 10000 | AO2: =MIN(MAX(EV_DB[[#This Row],[Federal Rebates (iMHZEV) ]],EV_DB[[#This Row],[NL Vehicle Rebates]]),PRODUCT(EV_DB[[#This Row],[Cost, $MSRP CAD]],0.75)) -> 10000 | AP2: =MIN(MAX(EV_DB[[#This Row],[Federal Rebates (iMHZEV) ]]+EV_DB[[#This Row],[YT Vehicle Rebates]]),PRODUCT(EV_DB[[#This Row],[Cost, $MSRP CAD]],0.75)) -> 10000 | AQ2: =MIN(MAX(EV_DB[[#This Row],[Federal Rebates (iMHZEV) ]],EV_DB[[#This Row],[NU Vehicle Rebates]]),PRODUCT(EV_DB[[#This Row],[Cost, $MSRP CAD]],0.75)) -> 10000 | AR2: =MIN(MAX(EV_DB[[#This Row],[Federal Rebates (iMHZEV) ]],EV_DB[[#This Row],[NT Vehicle Rebates]]),PRODUCT(EV_DB[[#This Row],[Cost, $MSRP CAD]],0.75)) -> 10000
A3: GMC | B3: GMC Sierra EV Denali Edition 1 | C3: =EV_DB[[#This Row],[Manufacturer ]]& " " &EV_DB[[#This Row],[Model]] -> GMC GMC Sierra EV Denali Edition 1 | D3: Pick-up truck | E3: 2025 | F3: 2B | G3: {=_xlfn.IFS(OR(EV_DB[[#This Row],[FHWA Class (2B - 8)]]= "2B", EV_DB[[#This Row],[FHWA Class (2B - 8)]]=3), "Light Duty",OR(EV_DB[[#This Row],[FHWA Class (2B - 8)]]=4,EV_DB[[#This Row],[FHWA Class (2B - 8)]]=5,EV_DB[[#This Row],[FHWA Class (2B - 8)]]=6),"Medium Duty",OR(EV_DB[[#This Row],[FHWA Class (2B - 8)]]=7,EV_DB[[#This Row],[FHWA Class (2B - 8)]]=8), "Heavy Duty")} -> Light Duty | H3: 9990 | I3: 1450 | J3: 92290 | K3: {=_xlfn.IFS(EV_DB[[#This Row],[Category]]="Light Duty",'Maintenance costs table'!$D$4,EV_DB[[#This Row],[Category]]="Medium Duty",'Maintenance costs table'!$D$8,EV_DB[[#This Row],[Category]]="Heavy Duty",'Maintenance costs table'!$D$6)} -> 0.18 | L3: No | M3: 205kwh | N3: 0.349 | O3: DC public fast-charging of 100 miles in approximately 10 minutes | Q3: 708.111 | R3: {=_xlfn.IFS(EV_DB[[#This Row],[Battery Size, kWh]]>350 & EV_DB[[#This Row],[FHWA Class (2B - 8)]]=8,'iMHZEV table'!$D$4,EV_DB[[#This Row],[Battery Size, kWh]]<=350 & EV_DB[[#This Row],[FHWA Class (2B - 8)]]=8,'iMHZEV table'!$D$5, TRUE, _xlfn.XLOOKUP(EV_DB[[#This Row],[FHWA Class (2B - 8)]],'iMHZEV table'!$A$3:$A$11,'iMHZEV table'!$D$3:$D$11))} -> 10000 | T3: {=_xlfn.IFS(EV_DB[[#This Row],[FHWA Class (2B - 8)]]= "2B",10000,EV_DB[[#This Row],[FHWA Class (2B - 8)]]=3,55000,OR(EV_DB[[#This Row],[FHWA Class (2B - 8)]]=4,EV_DB[[#This Row],[FHWA Class (2B - 8)]]=5), 75000,OR(EV_DB[[#This Row],[FHWA Class (2B - 8)]]=6,EV_DB[[#This Row],[FHWA Class (2B - 8)]]=7),100000,EV_DB[[#This Row],[FHWA Class (2B - 8)]]=8, 150000)} -> 10000 | AF3: =MIN(MAX(EV_DB[[#This Row],[Federal Rebates (iMHZEV) ]],EV_DB[[#This Row],[ON Vehicle Rebates]]),PRODUCT(EV_DB[[#This Row],[Cost, $MSRP CAD]],0.75)) -> 10000 | AG3: =MIN(EV_DB[[#This Row],[Federal Rebates (iMHZEV) ]]+EV_DB[[#This Row],[BC Vehicle Rebates]],PRODUCT(EV_DB[[#This Row],[Cost, $MSRP CAD]],0.75)) -> 20000 | AH3: =MIN(EV_DB[[#This Row],[Federal Rebates (iMHZEV) ]]+EV_DB[[#This Row],[QC Vehicle Rebates]],PRODUCT(EV_DB[[#This Row],[Cost, $MSRP CAD]],0.75)) -> 10000 | AI3: =MIN(MAX(EV_DB[[#This Row],[Federal Rebates (iMHZEV) ]],EV_DB[[#This Row],[AB Vehicle Rebates]]),PRODUCT(EV_DB[[#This Row],[Cost, $MSRP CAD]],0.75)) -> 10000 | AJ3: =MIN(MAX(EV_DB[[#This Row],[Federal Rebates (iMHZEV) ]],EV_DB[[#This Row],[SC Vehicle Rebates]]),PRODUCT(EV_DB[[#This Row],[Cost, $MSRP CAD]],0.75)) -> 10000 | AK3: =MIN(MAX(EV_DB[[#This Row],[Federal Rebates (iMHZEV) ]],EV_DB[[#This Row],[NS Vehicle Rebates]]),PRODUCT(EV_DB[[#This Row],[Cost, $MSRP CAD]],0.75)) -> 10000 | AL3: =MIN(MAX(EV_DB[[#This Row],[Federal Rebates (iMHZEV) ]],EV_DB[[#This Row],[NB Vehicle Rebates]]),PRODUCT(EV_DB[[#This Row],[Cost, $MSRP CAD]],0.75)) -> 10000 | AM3: =MIN(MAX(EV_DB[[#This Row],[Federal Rebates (iMHZEV) ]],EV_DB[[#This Row],[MB Vehicle Rebates]]),PRODUCT(EV_DB[[#This Row],[Cost, $MSRP CAD]],0.75)) -> 10000 | AN3: =MIN(MAX(EV_DB[[#This Row],[Federal Rebates (iMHZEV) ]],EV_DB[[#This Row],[PEI Vehicle Rebates]]),PRODUCT(EV_DB[[#This Row],[Cost, $MSRP CAD]],0.75)) -> 10000 | AO3: =MIN(MAX(EV_DB[[#This Row],[Federal Rebates (iMHZEV) ]],EV_DB[[#This Row],[NL Vehicle Rebates]]),PRODUCT(EV_DB[[#This Row],[Cost, $MSRP CAD]],0.75)) -> 10000 | AP3: =MIN(MAX(EV_DB[[#This Row],[Federal Rebates (iMHZEV) ]]+EV_DB[[#This Row],[YT Vehicle Rebates]]),PRODUCT(EV_DB[[#This Row],[Cost, $MSRP CAD]],0.75)) -> 10000 | AQ3: =MIN(MAX(EV_DB[[#This Row],[Federal Rebates (iMHZEV) ]],EV_DB[[#This Row],[NU Vehicle Rebates]]),PRODUCT(EV_DB[[#This Row],[Cost, $MSRP CAD]],0.75)) -> 10000 | AR3: =MIN(MAX(EV_DB[[#This Row],[Federal Rebates (iMHZEV) ]],EV_DB[[#This Row],[NT Vehicle Rebates]]),PRODUCT(EV_DB[[#This Row],[Cost, $MSRP CAD]],0.75)) -> 10000
A4: Chevrolet | B4: Silverado EV 3WT Max Range | C4: =EV_DB[[#This Row],[Manufacturer ]]& " " &EV_DB[[#This Row],[Model]] -> Chevrolet Silverado EV 3WT Max Range | D4: Pick-up truck | E4: 2025 | F4: 2B | G4: {=_xlfn.IFS(OR(EV_DB[[#This Row],[FHWA Class (2B - 8)]]= "2B", EV_DB[[#This Row],[FHWA Class (2B - 8)]]=3), "Light Duty",OR(EV_DB[[#This Row],[FHWA Class (2B - 8)]]=4,EV_DB[[#This Row],[FHWA Class (2B - 8)]]=5,EV_DB[[#This Row],[FHWA Class (2B - 8)]]=6),"Medium Duty",OR(EV_DB[[#This Row],[FHWA Class (2B - 8)]]=7,EV_DB[[#This Row],[FHWA Class (2B - 8)]]=8), "Heavy Duty")} -> Light Duty | H4: 9900 | I4: 1800 | J4: 85833 | K4: {=_xlfn.IFS(EV_DB[[#This Row],[Category]]="Light Duty",'Maintenance costs table'!$D$4,EV_DB[[#This Row],[Category]]="Medium Duty",'Maintenance costs table'!$D$8,EV_DB[[#This Row],[Category]]="Heavy Duty",'Maintenance costs table'!$D$6)} -> 0.18 | L4: No | M4: 205kwh | N4: 0.314 | O4: 11.5 kW capable onboard charging module 120V: N/A 240V: 11.0 h 400V: 0.5 h 10 minutes at a public DC charging station can add 100 miles of range. | Q4: 792 | R4: {=_xlfn.IFS(EV_DB[[#This Row],[Battery Size, kWh]]>350 & EV_DB[[#This Row],[FHWA Class (2B - 8)]]=8,'iMHZEV table'!$D$4,EV_DB[[#This Row],[Battery Size, kWh]]<=350 & EV_DB[[#This Row],[FHWA Class (2B - 8)]]=8,'iMHZEV table'!$D$5, TRUE, _xlfn.XLOOKUP(EV_DB[[#This Row],[FHWA Class (2B - 8)]],'iMHZEV table'!$A$3:$A$11,'iMHZEV table'!$D$3:$D$11))} -> 10000 | T4: {=_xlfn.IFS(EV_DB[[#This Row],[FHWA Class (2B - 8)]]= "2B",10000,EV_DB[[#This Row],[FHWA Class (2B - 8)]]=3,55000,OR(EV_DB[[#This Row],[FHWA Class (2B - 8)]]=4,EV_DB[[#This Row],[FHWA Class (2B - 8)]]=5), 75000,OR(EV_DB[[#This Row],[FHWA Class (2B - 8)]]=6,EV_DB[[#This Row],[FHWA Class (2B - 8)]]=7),100000,EV_DB[[#This Row],[FHWA Class (2B - 8)]]=8, 150000)} -> 10000 | AF4: =MIN(MAX(EV_DB[[#This Row],[Federal Rebates (iMHZEV) ]],EV_DB[[#This Row],[ON Vehicle Rebates]]),PRODUCT(EV_DB[[#This Row],[Cost, $MSRP CAD]],0.75)) -> 10000 | AG4: =MIN(EV_DB[[#This Row],[Federal Rebates (iMHZEV) ]]+EV_DB[[#This Row],[BC Vehicle Rebates]],PRODUCT(EV_DB[[#This Row],[Cost, $MSRP CAD]],0.75)) -> 20000 | AH4: =MIN(EV_DB[[#This Row],[Federal Rebates (iMHZEV) ]]+EV_DB[[#This Row],[QC Vehicle Rebates]],PRODUCT(EV_DB[[#This Row],[Cost, $MSRP CAD]],0.75)) -> 10000 | AI4: =MIN(MAX(EV_DB[[#This Row],[Federal Rebates (iMHZEV) ]],EV_DB[[#This Row],[AB Vehicle Rebates]]),PRODUCT(EV_DB[[#This Row],[Cost, $MSRP CAD]],0.75)) -> 10000 | AJ4: =MIN(MAX(EV_DB[[#This Row],[Federal Rebates (iMHZEV) ]],EV_DB[[#This Row],[SC Vehicle Rebates]]),PRODUCT(EV_DB[[#This Row],[Cost, $MSRP CAD]],0.75)) -> 10000 | AK4: =MIN(MAX(EV_DB[[#This Row],[Federal Rebates (iMHZEV) ]],EV_DB[[#This Row],[NS Vehicle Rebates]]),PRODUCT(EV_DB[[#This Row],[Cost, $MSRP CAD]],0.75)) -> 10000 | AL4: =MIN(MAX(EV_DB[[#This Row],[Federal Rebates (iMHZEV) ]],EV_DB[[#This Row],[NB Vehicle Rebates]]),PRODUCT(EV_DB[[#This Row],[Cost, $MSRP CAD]],0.75)) -> 10000 | AM4: =MIN(MAX(EV_DB[[#This Row],[Federal Rebates (iMHZEV) ]],EV_DB[[#This Row],[MB Vehicle Rebates]]),PRODUCT(EV_DB[[#This Row],[Cost, $MSRP CAD]],0.75)) -> 10000 | AN4: =MIN(MAX(EV_DB[[#This Row],[Federal Rebates (iMHZEV) ]],EV_DB[[#This Row],[PEI Vehicle Rebates]]),PRODUCT(EV_DB[[#This Row],[Cost, $MSRP CAD]],0.75)) -> 10000 | AO4: =MIN(MAX(EV_DB[[#This Row],[Federal Rebates (iMHZEV) ]],EV_DB[[#This Row],[NL Vehicle Rebates]]),PRODUCT(EV_DB[[#This Row],[Cost, $MSRP CAD]],0.75)) -> 10000 | AP4: =MIN(MAX(EV_DB[[#This Row],[Federal Rebates (iMHZEV) ]]+EV_DB[[#This Row],[YT Vehicle Rebates]]),PRODUCT(EV_DB[[#This Row],[Cost, $MSRP CAD]],0.75)) -> 10000 | AQ4: =MIN(MAX(EV_DB[[#This Row],[Federal Rebates (iMHZEV) ]],EV_DB[[#This Row],[NU Vehicle Rebates]]),PRODUCT(EV_DB[[#This Row],[Cost, $MSRP CAD]],0.75)) -> 10000 | AR4: =MIN(MAX(EV_DB[[#This Row],[Federal Rebates (iMHZEV) ]],EV_DB[[#This Row],[NT Vehicle Rebates]]),PRODUCT(EV_DB[[#This Row],[Cost, $MSRP CAD]],0.75)) -> 10000
A5: Chevrolet | B5: Silverado EV LT E4WD | C5: =EV_DB[[#This Row],[Manufacturer ]]& " " &EV_DB[[#This Row],[Model]] -> Chevrolet Silverado EV LT E4WD | D5: Pick-up truck | E5: 2025 | F5: 2B | G5: {=_xlfn.IFS(OR(EV_DB[[#This Row],[FHWA Class (2B - 8)]]= "2B", EV_DB[[#This Row],[FHWA Class (2B - 8)]]=3), "Light Duty",OR(EV_DB[[#This Row],[FHWA Class (2B - 8)]]=4,EV_DB[[#This Row],[FHWA Class (2B - 8)]]=5,EV_DB[[#This Row],[FHWA Class (2B - 8)]]=6),"Medium Duty",OR(EV_DB[[#This Row],[FHWA Class (2B - 8)]]=7,EV_DB[[#This Row],[FHWA Class (2B - 8)]]=8), "Heavy Duty")} -> Light Duty | H5: 9990 | I5: 1800 | J5: 95833 | K5: {=_xlfn.IFS(EV_DB[[#This Row],[Category]]="Light Duty",'Maintenance costs table'!$D$4,EV_DB[[#This Row],[Category]]="Medium Duty",'Maintenance costs table'!$D$8,EV_DB[[#This Row],[Category]]="Heavy Duty",'Maintenance costs table'!$D$6)} -> 0.18 | L5: No | M5: 170kwh | N5: 0.308 | O5: 11.5 kW capable onboard charging module 120V: N/A 240V: 11.0 h 400V: 0.5 h 10 minutes at a public DC charging station can add 100 miles of range. | Q5: 740 | R5: {=_xlfn.IFS(EV_DB[[#This Row],[Battery Size, kWh]]>350 & EV_DB[[#This Row],[FHWA Class (2B - 8)]]=8,'iMHZEV table'!$D$4,EV_DB[[#This Row],[Battery Size, kWh]]<=350 & EV_DB[[#This Row],[FHWA Class (2B - 8)]]=8,'iMHZEV table'!$D$5, TRUE, _xlfn.XLOOKUP(EV_DB[[#This Row],[FHWA Class (2B - 8)]],'iMHZEV table'!$A$3:$A$11,'iMHZEV table'!$D$3:$D$11))} -> 10000 | T5: {=_xlfn.IFS(EV_DB[[#This Row],[FHWA Class (2B - 8)]]= "2B",10000,EV_DB[[#This Row],[FHWA Class (2B - 8)]]=3,55000,OR(EV_DB[[#This Row],[FHWA Class (2B - 8)]]=4,EV_DB[[#This Row],[FHWA Class (2B - 8)]]=5), 75000,OR(EV_DB[[#This Row],[FHWA Class (2B - 8)]]=6,EV_DB[[#This Row],[FHWA Class (2B - 8)]]=7),100000,EV_DB[[#This Row],[FHWA Class (2B - 8)]]=8, 150000)} -> 10000 | AF5: =MIN(MAX(EV_DB[[#This Row],[Federal Rebates (iMHZEV) ]],EV_DB[[#This Row],[ON Vehicle Rebates]]),PRODUCT(EV_DB[[#This Row],[Cost, $MSRP CAD]],0.75)) -> 10000 | AG5: =MIN(EV_DB[[#This Row],[Federal Rebates (iMHZEV) ]]+EV_DB[[#This Row],[BC Vehicle Rebates]],PRODUCT(EV_DB[[#This Row],[Cost, $MSRP CAD]],0.75)) -> 20000 | AH5: =MIN(EV_DB[[#This Row],[Federal Rebates (iMHZEV) ]]+EV_DB[[#This Row],[QC Vehicle Rebates]],PRODUCT(EV_DB[[#This Row],[Cost, $MSRP CAD]],0.75)) -> 10000 | AI5: =MIN(MAX(EV_DB[[#This Row],[Federal Rebates (iMHZEV) ]],EV_DB[[#This Row],[AB Vehicle Rebates]]),PRODUCT(EV_DB[[#This Row],[Cost, $MSRP CAD]],0.75)) -> 10000 | AJ5: =MIN(MAX(EV_DB[[#This Row],[Federal Rebates (iMHZEV) ]],EV_DB[[#This Row],[SC Vehicle Rebates]]),PRODUCT(EV_DB[[#This Row],[Cost, $MSRP CAD]],0.75)) -> 10000 | AK5: =MIN(MAX(EV_DB[[#This Row],[Federal Rebates (iMHZEV) ]],EV_DB[[#This Row],[NS Vehicle Rebates]]),PRODUCT(EV_DB[[#This Row],[Cost, $MSRP CAD]],0.75)) -> 10000 | AL5: =MIN(MAX(EV_DB[[#This Row],[Federal Rebates (iMHZEV) ]],EV_DB[[#This Row],[NB Vehicle Rebates]]),PRODUCT(EV_DB[[#This Row],[Cost, $MSRP CAD]],0.75)) -> 10000 | AM5: =MIN(MAX(EV_DB[[#This Row],[Federal Rebates (iMHZEV) ]],EV_DB[[#This Row],[MB Vehicle Rebates]]),PRODUCT(EV_DB[[#This Row],[Cost, $MSRP CAD]],0.75)) -> 10000 | AN5: =MIN(MAX(EV_DB[[#This Row],[Federal Rebates (iMHZEV) ]],EV_DB[[#This Row],[PEI Vehicle Rebates]]),PRODUCT(EV_DB[[#This Row],[Cost, $MSRP CAD]],0.75)) -> 10000 | AO5: =MIN(MAX(EV_DB[[#This Row],[Federal Rebates (iMHZEV) ]],EV_DB[[#This Row],[NL Vehicle Rebates]]),PRODUCT(EV_DB[[#This Row],[Cost, $MSRP CAD]],0.75)) -> 10000 | AP5: =MIN(MAX(EV_DB[[#This Row],[Federal Rebates (iMHZEV) ]]+EV_DB[[#This Row],[YT Vehicle Rebates]]),PRODUCT(EV_DB[[#This Row],[Cost, $MSRP CAD]],0.75)) -> 10000 | AQ5: =MIN(MAX(EV_DB[[#This Row],[Federal Rebates (iMHZEV) ]],EV_DB[[#This Row],[NU Vehicle Rebates]]),PRODUCT(EV_DB[[#This Row],[Cost, $MSRP CAD]],0.75)) -> 10000 | AR5: =MIN(MAX(EV_DB[[#This Row],[Federal Rebates (iMHZEV) ]],EV_DB[[#This Row],[NT Vehicle Rebates]]),PRODUCT(EV_DB[[#This Row],[Cost, $MSRP CAD]],0.75)) -> 10000
A6: Ford | B6: F 150 Lightning | C6: =EV_DB[[#This Row],[Manufacturer ]]& " " &EV_DB[[#This Row],[Model]] -> Ford F 150 Lightning | D6: Pick-up truck | E6: 2025 | F6: 2B | G6: {=_xlfn.IFS(OR(EV_DB[[#This Row],[FHWA Class (2B - 8)]]= "2B", EV_DB[[#This Row],[FHWA Class (2B - 8)]]=3), "Light Duty",OR(EV_DB[[#This Row],[FHWA Class (2B - 8)]]=4,EV_DB[[#This Row],[FHWA Class (2B - 8)]]=5,EV_DB[[#This Row],[FHWA Class (2B - 8)]]=6),"Medium Duty",OR(EV_DB[[#This Row],[FHWA Class (2B - 8)]]=7,EV_DB[[#This Row],[FHWA Class (2B - 8)]]=8), "Heavy Duty")} -> Light Duty | H6: 8550 | I6: 2235 | J6: 62890 | K6: {=_xlfn.IFS(EV_DB[[#This Row],[Category]]="Light Duty",'Maintenance costs table'!$D$4,EV_DB[[#This Row],[Category]]="Medium Duty",'Maintenance costs table'!$D$8,EV_DB[[#This Row],[Category]]="Heavy Duty",'Maintenance costs table'!$D$6)} -> 0.18 | L6: No | M6: 98 kWh | N6: 0.254 | O6: 15% to 80% with a 150+ kW DC fast charger takes about 36 minutes for the Standard Range and | Q6: 386 | R6: {=_xlfn.IFS(EV_DB[[#This Row],[Battery Size, kWh]]>350 & EV_DB[[#This Row],[FHWA Class (2B - 8)]]=8,'iMHZEV table'!$D$4,EV_DB[[#This Row],[Battery Size, kWh]]<=350 & EV_DB[[#This Row],[FHWA Class (2B - 8)]]=8,'iMHZEV table'!$D$5, TRUE, _xlfn.XLOOKUP(EV_DB[[#This Row],[FHWA Class (2B - 8)]],'iMHZEV table'!$A$3:$A$11,'iMHZEV table'!$D$3:$D$11))} -> 10000 | T6: {=_xlfn.IFS(EV_DB[[#This Row],[FHWA Class (2B - 8)]]= "2B",10000,EV_DB[[#This Row],[FHWA Class (2B - 8)]]=3,55000,OR(EV_DB[[#This Row],[FHWA Class (2B - 8)]]=4,EV_DB[[#This Row],[FHWA Class (2B - 8)]]=5), 75000,OR(EV_DB[[#This Row],[FHWA Class (2B - 8)]]=6,EV_DB[[#This Row],[FHWA Class (2B - 8)]]=7),100000,EV_DB[[#This Row],[FHWA Class (2B - 8)]]=8, 150000)} -> 10000 | AF6: =MIN(MAX(EV_DB[[#This Row],[Federal Rebates (iMHZEV) ]],EV_DB[[#This Row],[ON Vehicle Rebates]]),PRODUCT(EV_DB[[#This Row],[Cost, $MSRP CAD]],0.75)) -> 10000 | AG6: =MIN(EV_DB[[#This Row],[Federal Rebates (iMHZEV) ]]+EV_DB[[#This Row],[BC Vehicle Rebates]],PRODUCT(EV_DB[[#This Row],[Cost, $MSRP CAD]],0.75)) -> 20000 | AH6: =MIN(EV_DB[[#This Row],[Federal Rebates (iMHZEV) ]]+EV_DB[[#This Row],[QC Vehicle Rebates]],PRODUCT(EV_DB[[#This Row],[Cost, $MSRP CAD]],0.75)) -> 10000 | AI6: =MIN(MAX(EV_DB[[#This Row],[Federal Rebates (iMHZEV) ]],EV_DB[[#This Row],[AB Vehicle Rebates]]),PRODUCT(EV_DB[[#This Row],[Cost, $MSRP CAD]],0.75)) -> 10000 | AJ6: =MIN(MAX(EV_DB[[#This Row],[Federal Rebates (iMHZEV) ]],EV_DB[[#This Row],[SC Vehicle Rebates]]),PRODUCT(EV_DB[[#This Row],[Cost, $MSRP CAD]],0.75)) -> 10000 | AK6: =MIN(MAX(EV_DB[[#This Row],[Federal Rebates (iMHZEV) ]],EV_DB[[#This Row],[NS Vehicle Rebates]]),PRODUCT(EV_DB[[#This Row],[Cost, $MSRP CAD]],0.75)) -> 10000 | AL6: =MIN(MAX(EV_DB[[#This Row],[Federal Rebates (iMHZEV) ]],EV_DB[[#This Row],[NB Vehicle Rebates]]),PRODUCT(EV_DB[[#This Row],[Cost, $MSRP CAD]],0.75)) -> 10000 | AM6: =MIN(MAX(EV_DB[[#This Row],[Federal Rebates (iMHZEV) ]],EV_DB[[#This Row],[MB Vehicle Rebates]]),PRODUCT(EV_DB[[#This Row],[Cost, $MSRP CAD]],0.75)) -> 10000 | AN6: =MIN(MAX(EV_DB[[#This Row],[Federal Rebates (iMHZEV) ]],EV_DB[[#This Row],[PEI Vehicle Rebates]]),PRODUCT(EV_DB[[#This Row],[Cost, $MSRP CAD]],0.75)) -> 10000 | AO6: =MIN(MAX(EV_DB[[#This Row],[Federal Rebates (iMHZEV) ]],EV_DB[[#This Row],[NL Vehicle Rebates]]),PRODUCT(EV_DB[[#This Row],[Cost, $MSRP CAD]],0.75)) -> 10000 | AP6: =MIN(MAX(EV_DB[[#This Row],[Federal Rebates (iMHZEV) ]]+EV_DB[[#This Row],[YT Vehicle Rebates]]),PRODUCT(EV_DB[[#This Row],[Cost, $MSRP CAD]],0.75)) -> 10000 | AQ6: =MIN(MAX(EV_DB[[#This Row],[Federal Rebates (iMHZEV) ]],EV_DB[[#This Row],[NU Vehicle Rebates]]),PRODUCT(EV_DB[[#This Row],[Cost, $MSRP CAD]],0.75)) -> 10000 | AR6: =MIN(MAX(EV_DB[[#This Row],[Federal Rebates (iMHZEV) ]],EV_DB[[#This Row],[NT Vehicle Rebates]]),PRODUCT(EV_DB[[#This Row],[Cost, $MSRP CAD]],0.75)) -> 10000
A7: Ford | B7: F 150 Lightning Flash and Lariat | C7: =EV_DB[[#This Row],[Manufacturer ]]& " " &EV_DB[[#This Row],[Model]] -> Ford F 150 Lightning Flash and Lariat | D7: Pick-up truck | E7: 2025 | F7: 2B | G7: {=_xlfn.IFS(OR(EV_DB[[#This Row],[FHWA Class (2B - 8)]]= "2B", EV_DB[[#This Row],[FHWA Class (2B - 8)]]=3), "Light Duty",OR(EV_DB[[#This Row],[FHWA Class (2B - 8)]]=4,EV_DB[[#This Row],[FHWA Class (2B - 8)]]=5,EV_DB[[#This Row],[FHWA Class (2B - 8)]]=6),"Medium Duty",OR(EV_DB[[#This Row],[FHWA Class (2B - 8)]]=7,EV_DB[[#This Row],[FHWA Class (2B - 8)]]=8), "Heavy Duty")} -> Light Duty | H7: 8550 | I7: 2235 | J7: 79090 | K7: {=_xlfn.IFS(EV_DB[[#This Row],[Category]]="Light Duty",'Maintenance costs table'!$D$4,EV_DB[[#This Row],[Category]]="Medium Duty",'Maintenance costs table'!$D$8,EV_DB[[#This Row],[Category]]="Heavy Duty",'Maintenance costs table'!$D$6)} -> 0.18 | L7: No | M7: 131 kWh | N7: 0.265 | O7: 150+ kW DC fast charger - 41 minutes for the Extended Range | Q7: 515 | R7: {=_xlfn.IFS(EV_DB[[#This Row],[Battery Size, kWh]]>350 & EV_DB[[#This Row],[FHWA Class (2B - 8)]]=8,'iMHZEV table'!$D$4,EV_DB[[#This Row],[Battery Size, kWh]]<=350 & EV_DB[[#This Row],[FHWA Class (2B - 8)]]=8,'iMHZEV table'!$D$5, TRUE, _xlfn.XLOOKUP(EV_DB[[#This Row],[FHWA Class (2B - 8)]],'iMHZEV table'!$A$3:$A$11,'iMHZEV table'!$D$3:$D$11))} -> 10000 | T7: {=_xlfn.IFS(EV_DB[[#This Row],[FHWA Class (2B - 8)]]= "2B",10000,EV_DB[[#This Row],[FHWA Class (2B - 8)]]=3,55000,OR(EV_DB[[#This Row],[FHWA Class (2B - 8)]]=4,EV_DB[[#This Row],[FHWA Class (2B - 8)]]=5), 75000,OR(EV_DB[[#This Row],[FHWA Class (2B - 8)]]=6,EV_DB[[#This Row],[FHWA Class (2B - 8)]]=7),100000,EV_DB[[#This Row],[FHWA Class (2B - 8)]]=8, 150000)} -> 10000 | AF7: =MIN(MAX(EV_DB[[#This Row],[Federal Rebates (iMHZEV) ]],EV_DB[[#This Row],[ON Vehicle Rebates]]),PRODUCT(EV_DB[[#This Row],[Cost, $MSRP CAD]],0.75)) -> 10000 | AG7: =MIN(EV_DB[[#This Row],[Federal Rebates (iMHZEV) ]]+EV_DB[[#This Row],[BC Vehicle Rebates]],PRODUCT(EV_DB[[#This Row],[Cost, $MSRP CAD]],0.75)) -> 20000 | AH7: =MIN(EV_DB[[#This Row],[Federal Rebates (iMHZEV) ]]+EV_DB[[#This Row],[QC Vehicle Rebates]],PRODUCT(EV_DB[[#This Row],[Cost, $MSRP CAD]],0.75)) -> 10000 | AI7: =MIN(MAX(EV_DB[[#This Row],[Federal Rebates (iMHZEV) ]],EV_DB[[#This Row],[AB Vehicle Rebates]]),PRODUCT(EV_DB[[#This Row],[Cost, $MSRP CAD]],0.75)) -> 10000 | AJ7: =MIN(MAX(EV_DB[[#This Row],[Federal Rebates (iMHZEV) ]],EV_DB[[#This Row],[SC Vehicle Rebates]]),PRODUCT(EV_DB[[#This Row],[Cost, $MSRP CAD]],0.75)) -> 10000 | AK7: =MIN(MAX(EV_DB[[#This Row],[Federal Rebates (iMHZEV) ]],EV_DB[[#This Row],[NS Vehicle Rebates]]),PRODUCT(EV_DB[[#This Row],[Cost, $MSRP CAD]],0.75)) -> 10000 | AL7: =MIN(MAX(EV_DB[[#This Row],[Federal Rebates (iMHZEV) ]],EV_DB[[#This Row],[NB Vehicle Rebates]]),PRODUCT(EV_DB[[#This Row],[Cost, $MSRP CAD]],0.75)) -> 10000 | AM7: =MIN(MAX(EV_DB[[#This Row],[Federal Rebates (iMHZEV) ]],EV_DB[[#This Row],[MB Vehicle Rebates]]),PRODUCT(EV_DB[[#This Row],[Cost, $MSRP CAD]],0.75)) -> 10000 | AN7: =MIN(MAX(EV_DB[[#This Row],[Federal Rebates (iMHZEV) ]],EV_DB[[#This Row],[PEI Vehicle Rebates]]),PRODUCT(EV_DB[[#This Row],[Cost, $MSRP CAD]],0.75)) -> 10000 | AO7: =MIN(MAX(EV_DB[[#This Row],[Federal Rebates (iMHZEV) ]],EV_DB[[#This Row],[NL Vehicle Rebates]]),PRODUCT(EV_DB[[#This Row],[Cost, $MSRP CAD]],0.75)) -> 10000 | AP7: =MIN(MAX(EV_DB[[#This Row],[Federal Rebates (iMHZEV) ]]+EV_DB[[#This Row],[YT Vehicle Rebates]]),PRODUCT(EV_DB[[#This Row],[Cost, $MSRP CAD]],0.75)) -> 10000 | AQ7: =MIN(MAX(EV_DB[[#This Row],[Federal Rebates (iMHZEV) ]],EV_DB[[#This Row],[NU Vehicle Rebates]]),PRODUCT(EV_DB[[#This Row],[Cost, $MSRP CAD]],0.75)) -> 10000 | AR7: =MIN(MAX(EV_DB[[#This Row],[Federal Rebates (iMHZEV) ]],EV_DB[[#This Row],[NT Vehicle Rebates]]),PRODUCT(EV_DB[[#This Row],[Cost, $MSRP CAD]],0.75)) -> 10000
